2019-01-07 17:36:22,567 [ERROR] runcase.py line:118: *** From Excel import testsuite fail ***
Traceback (most recent call last):
  File "E:/py_workspaces/clearbug\sweetest\runcase.py", line 113, in run
    testsuite=testsuite_format4database(TestCase_haptest.objects.get_dicts(RunCase.objects.get_testcases(runcase_name=runcase_name)))
  File "E:/py_workspaces/clearbug\haptest\managers.py", line 42, in get_dicts
    steps=queryset_class.get(case["id"]).casestep_set().values()
  File "E:\py_workspaces\clearbug\venv\lib\site-packages\django\db\models\query.py", line 390, in get
    clone = self.filter(*args, **kwargs)
  File "E:\py_workspaces\clearbug\venv\lib\site-packages\django\db\models\query.py", line 844, in filter
    return self._filter_or_exclude(False, *args, **kwargs)
  File "E:\py_workspaces\clearbug\venv\lib\site-packages\django\db\models\query.py", line 862, in _filter_or_exclude
    clone.query.add_q(Q(*args, **kwargs))
  File "E:\py_workspaces\clearbug\venv\lib\site-packages\django\db\models\sql\query.py", line 1263, in add_q
    clause, _ = self._add_q(q_object, self.used_aliases)
  File "E:\py_workspaces\clearbug\venv\lib\site-packages\django\db\models\sql\query.py", line 1287, in _add_q
    split_subq=split_subq,
  File "E:\py_workspaces\clearbug\venv\lib\site-packages\django\db\models\sql\query.py", line 1161, in build_filter
    arg, value = filter_expr
TypeError: 'int' object is not iterable
2019-01-07 17:37:08,885 [ERROR] runcase.py line:118: *** From Excel import testsuite fail ***
Traceback (most recent call last):
  File "E:/py_workspaces/clearbug\sweetest\runcase.py", line 113, in run
    testsuite=testsuite_format4database(TestCase_haptest.objects.get_dicts(RunCase.objects.get_testcases(runcase_name=runcase_name)))
  File "E:/py_workspaces/clearbug\haptest\managers.py", line 42, in get_dicts
    steps=queryset_class.get(case["id"]).casestep_set().values()
  File "E:\py_workspaces\clearbug\venv\lib\site-packages\django\db\models\query.py", line 390, in get
    clone = self.filter(*args, **kwargs)
  File "E:\py_workspaces\clearbug\venv\lib\site-packages\django\db\models\query.py", line 844, in filter
    return self._filter_or_exclude(False, *args, **kwargs)
  File "E:\py_workspaces\clearbug\venv\lib\site-packages\django\db\models\query.py", line 862, in _filter_or_exclude
    clone.query.add_q(Q(*args, **kwargs))
  File "E:\py_workspaces\clearbug\venv\lib\site-packages\django\db\models\sql\query.py", line 1263, in add_q
    clause, _ = self._add_q(q_object, self.used_aliases)
  File "E:\py_workspaces\clearbug\venv\lib\site-packages\django\db\models\sql\query.py", line 1287, in _add_q
    split_subq=split_subq,
  File "E:\py_workspaces\clearbug\venv\lib\site-packages\django\db\models\sql\query.py", line 1161, in build_filter
    arg, value = filter_expr
TypeError: 'int' object is not iterable
2019-01-07 18:15:50,725 [ERROR] runcase.py line:118: *** From Excel import testsuite fail ***
Traceback (most recent call last):
  File "E:/py_workspaces/clearbug\sweetest\runcase.py", line 113, in run
    testsuite=testsuite_format4database(TestCase_haptest.objects.get_dicts(RunCase.objects.get_testcases(runcase_name=runcase_name)))
  File "E:/py_workspaces/clearbug\sweetest\data.py", line 128, in testsuite_format4database
    step['no'] = str(int(d['step']))
KeyError: 'step'
2019-01-07 18:18:53,390 [ERROR] runcase.py line:118: *** From Excel import testsuite fail ***
Traceback (most recent call last):
  File "E:/py_workspaces/clearbug\sweetest\runcase.py", line 113, in run
    testsuite=testsuite_format4database(TestCase_haptest.objects.get_dicts(RunCase.objects.get_testcases(runcase_name=runcase_name)))
  File "E:/py_workspaces/clearbug\sweetest\data.py", line 133, in testsuite_format4database
    step['_keyword'] = d['keyword']
KeyError: 'keyword'
2019-01-07 18:22:00,064 [ERROR] runcase.py line:118: *** From Excel import testsuite fail ***
Traceback (most recent call last):
  File "E:/py_workspaces/clearbug\sweetest\runcase.py", line 113, in run
    testsuite=testsuite_format4database(TestCase_haptest.objects.get_dicts(RunCase.objects.get_testcases(runcase_name=runcase_name)))
  File "E:/py_workspaces/clearbug\sweetest\data.py", line 139, in testsuite_format4database
    testcase['steps'].append(step)
KeyError: 'steps'
2019-01-07 18:25:30,469 [INFO] runcase.py line:116: From Excel import testsuite success
2019-01-07 18:25:33,765 [ERROR] runcase.py line:139: *** Init global object fail ***
Traceback (most recent call last):
  File "E:/py_workspaces/clearbug\sweetest\runcase.py", line 132, in run
    g.var=Data.objects.get_dict(project=self.project_id)
  File "E:/py_workspaces/clearbug\haptest\managers.py", line 19, in get_dict
    data_first.update(flag="Y")
  File "E:\py_workspaces\clearbug\venv\lib\site-packages\django\db\models\query.py", line 686, in update
    "Cannot update a query once a slice has been taken."
AssertionError: Cannot update a query once a slice has been taken.
2019-01-07 18:31:16,887 [INFO] runcase.py line:116: From Excel import testsuite success
2019-01-07 18:31:44,346 [ERROR] runcase.py line:139: *** Init global object fail ***
Traceback (most recent call last):
  File "E:/py_workspaces/clearbug\sweetest\runcase.py", line 132, in run
    g.var=Data.objects.get_dict(project=self.project_id)
  File "E:/py_workspaces/clearbug\haptest\managers.py", line 20, in get_dict
    super().get(pk=data_first.id).update(flag="Y")
AttributeError: 'QuerySet' object has no attribute 'id'
2019-01-07 18:35:39,846 [INFO] runcase.py line:116: From Excel import testsuite success
2019-01-07 18:35:42,719 [ERROR] runcase.py line:139: *** Init global object fail ***
Traceback (most recent call last):
  File "E:/py_workspaces/clearbug\sweetest\runcase.py", line 132, in run
    g.var=Data.objects.get_dict(project=self.project_id)
  File "E:/py_workspaces/clearbug\haptest\managers.py", line 20, in get_dict
    super().get(pk=data_first.get().id).update(flag="Y")
AttributeError: 'Data' object has no attribute 'update'
